2020-08-13 09:25:37,527 : INFO : Start of Training
2020-08-13 09:25:37,527 : INFO : Run_id:2020-08-13_092537_855888679
2020-08-13 09:25:37,527 : INFO : Start of Data Load, validation and transformation
2020-08-13 09:25:37,527 : INFO : Start of Archiving Old Rejected Files...
2020-08-13 09:25:37,527 : INFO : End of Archiving Old Rejected Files...
2020-08-13 09:25:37,527 : INFO : Start of Archiving Old Validated Files...
2020-08-13 09:25:37,528 : INFO : End of Archiving Old Validated Files...
2020-08-13 09:25:37,528 : INFO : Start of Archiving Old Processed Files...
2020-08-13 09:25:37,529 : INFO : End of Archiving Old Processed Files...
2020-08-13 09:25:37,530 : INFO : Start of Archiving Old Result Files...
2020-08-13 09:25:38,423 : INFO : End of Archiving Old Result Files...
2020-08-13 09:25:38,424 : INFO : Start of Reading values From Schema...
2020-08-13 09:25:38,426 : INFO : End of Reading values From Schema...
2020-08-13 09:25:38,427 : INFO : Start of Validating Column Length...
2020-08-13 09:25:38,510 : INFO : End of Validating Column Length...
2020-08-13 09:25:38,510 : INFO : Start of Validating Missing Values...
2020-08-13 09:25:38,536 : INFO : End of Validating Missing Values...
2020-08-13 09:25:38,536 : INFO : Start of Replacing Missing Values with NULL...
2020-08-13 09:25:38,572 : INFO : Credit_Approval_rename_data.csv: File Transformed successfully!!
2020-08-13 09:25:38,572 : INFO : End of Replacing Missing Values with NULL...
2020-08-13 09:25:38,572 : INFO : Start of Creating Table...
2020-08-13 09:25:38,573 : INFO : Opened training database successfully
2020-08-13 09:25:38,574 : INFO : Tables created successfully
2020-08-13 09:25:38,574 : INFO : Closed training database successfully
2020-08-13 09:25:38,574 : INFO : End of Creating Table...
2020-08-13 09:25:38,575 : INFO : Opened training database successfully
2020-08-13 09:25:38,575 : INFO : Start of Inserting Data into Table...
2020-08-13 09:27:04,834 : INFO : End of Inserting Data into Table...
2020-08-13 09:27:04,836 : INFO : Start of Exporting Data into CSV...
2020-08-13 09:27:04,842 : INFO : Opened training database successfully
2020-08-13 09:27:04,892 : INFO : End of Exporting Data into CSV...
2020-08-13 09:27:04,892 : INFO : Start of Moving Processed Files...
2020-08-13 09:27:04,894 : INFO : Moved the already processed file Credit_Approval_rename_data.csv
2020-08-13 09:27:04,894 : INFO : End of Moving Processed Files...
2020-08-13 09:27:04,894 : INFO : End of Data Load, validation and transformation
2020-08-13 09:27:04,894 : INFO : Start of Preprocessing...
2020-08-13 09:27:04,895 : INFO : Start of reading dataset...
2020-08-13 09:27:04,910 : INFO : End of reading dataset...
2020-08-13 09:27:04,910 : INFO : Start of Droping Columns...
2020-08-13 09:27:04,912 : INFO : End of Droping Columns...
2020-08-13 09:27:04,912 : INFO : Start of replacing invalid values...
2020-08-13 09:27:04,943 : INFO : end of replacing invalid values...
2020-08-13 09:27:04,943 : INFO : Start of encode Categorical Values ...
2020-08-13 09:27:04,945 : ERROR : Exception raised while splitting features and label:No numeric types to aggregate
Traceback (most recent call last):
  File "C:\Users\sreeh\Desktop\group project\actual project\apps\preprocess\preprocessor.py", line 201, in encodeCategoricalValues
    EducationLevel_encoding = data.groupby(['EducationLevel'])['Approved'].mean().to_dict()
  File "C:\Users\sreeh\anaconda3\envs\Credit_Approval\lib\site-packages\pandas\core\groupby\groupby.py", line 1205, in mean
    "mean", alt=lambda x, axis: Series(x).mean(**kwargs), **kwargs
  File "C:\Users\sreeh\anaconda3\envs\Credit_Approval\lib\site-packages\pandas\core\groupby\groupby.py", line 888, in _cython_agg_general
    raise DataError("No numeric types to aggregate")
pandas.core.base.DataError: No numeric types to aggregate
2020-08-13 09:27:04,948 : ERROR : Unsuccessful End of Preprocessing...
Traceback (most recent call last):
  File "C:\Users\sreeh\Desktop\group project\actual project\apps\preprocess\preprocessor.py", line 201, in encodeCategoricalValues
    EducationLevel_encoding = data.groupby(['EducationLevel'])['Approved'].mean().to_dict()
  File "C:\Users\sreeh\anaconda3\envs\Credit_Approval\lib\site-packages\pandas\core\groupby\groupby.py", line 1205, in mean
    "mean", alt=lambda x, axis: Series(x).mean(**kwargs), **kwargs
  File "C:\Users\sreeh\anaconda3\envs\Credit_Approval\lib\site-packages\pandas\core\groupby\groupby.py", line 888, in _cython_agg_general
    raise DataError("No numeric types to aggregate")
pandas.core.base.DataError: No numeric types to aggregate

During handling of the above exception, another exception occurred:

Traceback (most recent call last):
  File "C:\Users\sreeh\Desktop\group project\actual project\apps\preprocess\preprocessor.py", line 327, in preprocess_trainset
    data = self.encodeCategoricalValues(data)
  File "C:\Users\sreeh\Desktop\group project\actual project\apps\preprocess\preprocessor.py", line 218, in encodeCategoricalValues
    raise Exception()
Exception
2020-08-13 09:27:04,949 : ERROR : Unsuccessful End of Training
Traceback (most recent call last):
  File "C:\Users\sreeh\Desktop\group project\actual project\apps\preprocess\preprocessor.py", line 201, in encodeCategoricalValues
    EducationLevel_encoding = data.groupby(['EducationLevel'])['Approved'].mean().to_dict()
  File "C:\Users\sreeh\anaconda3\envs\Credit_Approval\lib\site-packages\pandas\core\groupby\groupby.py", line 1205, in mean
    "mean", alt=lambda x, axis: Series(x).mean(**kwargs), **kwargs
  File "C:\Users\sreeh\anaconda3\envs\Credit_Approval\lib\site-packages\pandas\core\groupby\groupby.py", line 888, in _cython_agg_general
    raise DataError("No numeric types to aggregate")
pandas.core.base.DataError: No numeric types to aggregate

During handling of the above exception, another exception occurred:

Traceback (most recent call last):
  File "C:\Users\sreeh\Desktop\group project\actual project\apps\preprocess\preprocessor.py", line 327, in preprocess_trainset
    data = self.encodeCategoricalValues(data)
  File "C:\Users\sreeh\Desktop\group project\actual project\apps\preprocess\preprocessor.py", line 218, in encodeCategoricalValues
    raise Exception()
Exception

During handling of the above exception, another exception occurred:

Traceback (most recent call last):
  File "C:\Users\sreeh\Desktop\group project\actual project\apps\training\train_model.py", line 54, in training_model
    self.X, self.y = self.preProcess.preprocess_trainset()
  File "C:\Users\sreeh\Desktop\group project\actual project\apps\preprocess\preprocessor.py", line 347, in preprocess_trainset
    raise Exception
Exception
